Workbook

Sheet Overview
B2: Vernier · campus database
B3: Precision for campus life. Design reference and working mock of backend/vernier.db
B5: This workbook documents every table the Vernier backend stores, with realistic sample rows, validation that mirrors main.py, and a live dashboard. The real database is the SQLite file vernier.db on Arushi's laptop; this workbook does not sync with it. Treat it as the shared blueprint: when db.py changes, update it here.
B7: SHEETS
B8: Sheet | C8: What it holds | D8: Rows now | E8: Filled by
B9: Dashboard | C9: Live counts and charts across all tables | D9: n/a | E9: formulas
B10: Data_Dictionary | C10: Every column: type, allowed values, who writes and reads it | D10: n/a | E10: reference
B11: Intent_Map | C11: What each message type and endpoint does to the tables | D11: n/a | E11: reference
B12: SQL_Reference | C12: CREATE TABLE statements, the backend's queries, handy checks | D12: n/a | E12: reference
B13: lost_found | C13: Lost reports and found items, from chat and the shelf camera | D13: =COUNTA(lost_found!$A$2:$A$1000) -> 14 | E13: main.py, camera
B14: events | C14: Events, auditions, recruitments with category and major flag | D14: =COUNTA(events!$A$2:$A$1000) -> 10 | E14: main.py (event posts)
B15: listings | C15: Buy and sell posts | D15: =COUNTA(listings!$A$2:$A$1000) -> 7 | E15: main.py
B16: machines | C16: Washing machine status, one row per machine | D16: =COUNTA(machines!$A$2:$A$1000) -> 4 | E16: cv_machine.py
B17: bookings | C17: Room bookings (day, start, end) | D17: =COUNTA(bookings!$A$2:$A$1000) -> 5 | E17: main.py
B18: students | C18: Alert preferences: interests and level | D18: =COUNTA(students!$A$2:$A$1000) -> 6 | E18: DM command, app
B19: outbox | C19: Private alerts waiting for the bot to send | D19: =COUNTA(outbox!$A$2:$A$1000) -> 6 | E19: main.py
B20: Match_Check | C20: Formula check: does a found item exist for each lost report? | D20: n/a | E20: formulas
B21: Lists | C21: Dropdown values used by validation (edit here) | D21: n/a | E21: Arushi
B22: Change_Log | C22: Change procedure and proposed schema changes | D22: n/a | E22: Arushi
B24: HOW A LOST ITEM MOVES THROUGH lost_found.status
B25: open | C25: A new lost report or found item. Only open FOUND rows are offered as matches.
B26: matched | C26: Set on the LOST row when a matching found item arrives (chat post or camera). The owner gets a "Good news!" alert.
B27: claim_pending | C27: Set when someone DMs "claim <id>". The id is the FOUND item's row, so it is the found row that changes.
B28: claimed | C28: Set on a camera item when it is removed from the shelf. Chat-posted items have no automatic path to claimed yet.
B30: CONVENTIONS
B31: • Timestamps (created, updated) are ISO 8601 text: 2026-10-27T11:30:00. Date/time columns are formatted as text so Excel does not rewrite them.
B32: • Contacts are WhatsApp ids (91XXXXXXXXXX@c.us, or ...@lid). All ids in the sample rows are fictional placeholders.
B33: • Interests are lowercase and comma-separated with no spaces, so main.py's split matches them against categories.
B34: • Dropdowns and format checks on each table sheet mirror what main.py accepts. Format checks warn but allow override.
B35: • Add new rows directly under the last row. Dashboard, Match_Check and the counts above read down to row 1000.
B36: • Sample rows show every status and flow. Delete them before using this as a real record.
B38: COLOUR LEGEND
B39: Sample | C39: Input cell you may change (Dashboard reference date)
B40: Sample | C40: Column headers (match the real column names exactly)
B41: Sample | C41: Banded sample rows and totals
B42: Sample | C42: Good / done / free / sent
B43: Sample | C43: Needs attention / in use / claim pending

Sheet Dashboard
B1: Vernier dashboard
B2: Every number below is a live formula over the table sheets. Edit data there, not here.
B4: Reference date for room bookings | C4: 2026-10-27 | D4: Input (text, YYYY-MM-DD). Change it to see another day's bookings.
B6: LOST & FOUND
B7: Status | C7: Lost reports | D7: Found items | E7: Total
B8: open | C8: =COUNTIFS(lost_found!$B$2:$B$1000,"lost",lost_found!$I$2:$I$1000,$B8) -> 4 | D8: =COUNTIFS(lost_found!$B$2:$B$1000,"found",lost_found!$I$2:$I$1000,$B8) -> 7 | E8: =C8+D8 -> 11
B9: matched | C9: =COUNTIFS(lost_found!$B$2:$B$1000,"lost",lost_found!$I$2:$I$1000,$B9) -> 1 | D9: =COUNTIFS(lost_found!$B$2:$B$1000,"found",lost_found!$I$2:$I$1000,$B9) -> 0 | E9: =C9+D9 -> 1
B10: claim_pending | C10: =COUNTIFS(lost_found!$B$2:$B$1000,"lost",lost_found!$I$2:$I$1000,$B10) -> 0 | D10: =COUNTIFS(lost_found!$B$2:$B$1000,"found",lost_found!$I$2:$I$1000,$B10) -> 1 | E10: =C10+D10 -> 1
B11: claimed | C11: =COUNTIFS(lost_found!$B$2:$B$1000,"lost",lost_found!$I$2:$I$1000,$B11) -> 0 | D11: =COUNTIFS(lost_found!$B$2:$B$1000,"found",lost_found!$I$2:$I$1000,$B11) -> 1 | E11: =C11+D11 -> 1
B12: Total | C12: =SUM(C8:C11) -> 5 | D12: =SUM(D8:D11) -> 9 | E12: =SUM(E8:E11) -> 14
B14: Indicator | C14: Value | D14: How it is calculated
B15: Records from chat | C15: =COUNTIFS(lost_found!$H$2:$H$1000,"chat") -> 8 | D15: source = chat
B16: Records from shelf camera | C16: =COUNTIFS(lost_found!$H$2:$H$1000,"camera") -> 6 | D16: source = camera
B17: Camera share of all records | C17: =IF(E12=0,0,C16/E12) -> 0.42857143 | D17: camera records / all records
B18: Lost reports already matched | C18: =IF(C12=0,0,C9/C12) -> 0.2 | D18: lost rows with status 'matched' / all lost rows
B19: Found items waiting for an owner | C19: =D8 -> 7 | D19: found rows with status 'open'
B21: EVENTS & ALERT REACH
B22: Category | C22: Events | D22: Major events | E22: Followers: all alerts | F22: Followers: major only
B23: =Lists!B2 -> sports | C23: =COUNTIFS(events!$C$2:$C$1000,$B23) -> 1 | D23: =COUNTIFS(events!$C$2:$C$1000,$B23,events!$G$2:$G$1000,1) -> 1 | E23: =COUNTIFS(students!$B$2:$B$1000,"*"&$B23&"*",students!$C$2:$C$1000,"all") -> 1 | F23: =COUNTIFS(students!$B$2:$B$1000,"*"&$B23&"*",students!$C$2:$C$1000,"major") -> 1
B24: =Lists!B3 -> music | C24: =COUNTIFS(events!$C$2:$C$1000,$B24) -> 1 | D24: =COUNTIFS(events!$C$2:$C$1000,$B24,events!$G$2:$G$1000,1) -> 0 | E24: =COUNTIFS(students!$B$2:$B$1000,"*"&$B24&"*",students!$C$2:$C$1000,"all") -> 1 | F24: =COUNTIFS(students!$B$2:$B$1000,"*"&$B24&"*",students!$C$2:$C$1000,"major") -> 1
B25: =Lists!B4 -> dance | C25: =COUNTIFS(events!$C$2:$C$1000,$B25) -> 1 | D25: =COUNTIFS(events!$C$2:$C$1000,$B25,events!$G$2:$G$1000,1) -> 0 | E25: =COUNTIFS(students!$B$2:$B$1000,"*"&$B25&"*",students!$C$2:$C$1000,"all") -> 2 | F25: =COUNTIFS(students!$B$2:$B$1000,"*"&$B25&"*",students!$C$2:$C$1000,"major") -> 0
B26: =Lists!B5 -> theatre | C26: =COUNTIFS(events!$C$2:$C$1000,$B26) -> 1 | D26: =COUNTIFS(events!$C$2:$C$1000,$B26,events!$G$2:$G$1000,1) -> 0 | E26: =COUNTIFS(students!$B$2:$B$1000,"*"&$B26&"*",students!$C$2:$C$1000,"all") -> 0 | F26: =COUNTIFS(students!$B$2:$B$1000,"*"&$B26&"*",students!$C$2:$C$1000,"major") -> 1
B27: =Lists!B6 -> culture | C27: =COUNTIFS(events!$C$2:$C$1000,$B27) -> 2 | D27: =COUNTIFS(events!$C$2:$C$1000,$B27,events!$G$2:$G$1000,1) -> 2 | E27: =COUNTIFS(students!$B$2:$B$1000,"*"&$B27&"*",students!$C$2:$C$1000,"all") -> 0 | F27: =COUNTIFS(students!$B$2:$B$1000,"*"&$B27&"*",students!$C$2:$C$1000,"major") -> 1
B28: =Lists!B7 -> tech | C28: =COUNTIFS(events!$C$2:$C$1000,$B28) -> 2 | D28: =COUNTIFS(events!$C$2:$C$1000,$B28,events!$G$2:$G$1000,1) -> 1 | E28: =COUNTIFS(students!$B$2:$B$1000,"*"&$B28&"*",students!$C$2:$C$1000,"all") -> 2 | F28: =COUNTIFS(students!$B$2:$B$1000,"*"&$B28&"*",students!$C$2:$C$1000,"major") -> 0
B29: =Lists!B8 -> academic | C29: =COUNTIFS(events!$C$2:$C$1000,$B29) -> 1 | D29: =COUNTIFS(events!$C$2:$C$1000,$B29,events!$G$2:$G$1000,1) -> 0 | E29: =COUNTIFS(students!$B$2:$B$1000,"*"&$B29&"*",students!$C$2:$C$1000,"all") -> 1 | F29: =COUNTIFS(students!$B$2:$B$1000,"*"&$B29&"*",students!$C$2:$C$1000,"major") -> 0
B30: =Lists!B9 -> other | C30: =COUNTIFS(events!$C$2:$C$1000,$B30) -> 1 | D30: =COUNTIFS(events!$C$2:$C$1000,$B30,events!$G$2:$G$1000,1) -> 0 | E30: =COUNTIFS(students!$B$2:$B$1000,"*"&$B30&"*",students!$C$2:$C$1000,"all") -> 0 | F30: =COUNTIFS(students!$B$2:$B$1000,"*"&$B30&"*",students!$C$2:$C$1000,"major") -> 0
B31: Total | C31: =SUM(C23:C30) -> 10 | D31: =SUM(D23:D30) -> 4 | E31: =SUM(E23:E30) -> 7 | F31: =SUM(F23:F30) -> 4
B32: Followers are subscriptions: one student following three categories counts three times.
B34: BUY / SELL
B35: Metric | C35: Value
B36: Open sell listings | C36: =COUNTIFS(listings!$B$2:$B$1000,"sell",listings!$G$2:$G$1000,"open") -> 5
B37: Open buy requests | C37: =COUNTIFS(listings!$B$2:$B$1000,"buy",listings!$G$2:$G$1000,"open") -> 2
B38: All listings stored | C38: =COUNTA(listings!$A$2:$A$1000) -> 7
B40: LAUNDRY
B41: Metric | C41: Value
B42: Machines tracked | C42: =COUNTA(machines!$A$2:$A$1000) -> 4
B43: In use | C43: =COUNTIF(machines!$C$2:$C$1000,"in use") -> 2
B44: Free | C44: =COUNTIF(machines!$C$2:$C$1000,"free") -> 2
B45: Utilisation right now | C45: =IF(C42=0,0,C43/C42) -> 0.5
B47: ROOMS
...

Sheet Data_Dictionary
A1: Data dictionary: every column in vernier.db
A2: Mirrors init_db() in backend/db.py. If the two ever disagree, db.py wins; update this sheet and log the change in Change_Log.
A4: Table | B4: Column | C4: SQLite type | D4: Key | E4: Default | F4: Allowed values / format | G4: Filled by | H4: Read by | I4: Example | J4: Notes
A5: lost_found | B5: id | C5: INTEGER | D5: PK | E5: auto | F5: whole number >= 1 | G5: SQLite (auto) | H5: claim command, /camera/item/{id}/removed, bot replies, app | I5: 7 | J5: Students see this id in "claim <id>". The claim DM updates the row with that id, i.e. the FOUND item's row.
A6: lost_found | B6: kind | C6: TEXT | E6: none | F6: lost | found | G6: add_lost_found() in main.py | H6: find_matches(), ask_lost, app | I6: found | J6: No DEFAULT or CHECK in SQL: validity is enforced by main.py only.
A7: lost_found | B7: item | C7: TEXT | E7: none | F7: short noun, lowercase | G7: llm.extract (chat) / cv_shelf.py (camera) | H7: match_score(), replies, app | I7: earbuds | J7: Matching needs at least one shared word in item, so keep it a clean short noun ("earbuds", not "my black boat earbuds").
A8: lost_found | B8: colour | C8: TEXT | E8: none | F8: one simple word, or empty | G8: llm.extract / cv_shelf.py | H8: match_score(), replies | I8: black | J8: Colour words count in the Jaccard score; empty is allowed.
A9: lost_found | B9: place | C9: TEXT | E9: none | F9: free text | G9: llm.extract / camera shelf location | H9: replies ("found near ...") | I9: Rack C, Basket 3 | J9: Camera items store the shelf slot; chat items store whatever the student wrote.
A10: lost_found | B10: details | C10: TEXT | E10: none | F10: original message text; empty for camera items | G10: main.py (data["details"] = text) | H10: app, staff review | I10: found black earbuds near library desk | J10: PRIVACY: this keeps the full text a student typed, which can contain names or phone numbers. Not used by matching.
A11: lost_found | B11: contact | C11: TEXT | E11: none | F11: WhatsApp id: 91XXXXXXXXXX@c.us or ...@lid; empty for camera | G11: main.py (m.author) | H11: handle_found() to alert the owner | I11: 919800000001@c.us | J11: Newer accounts appear as @lid ids rather than phone numbers.
A12: lost_found | B12: source | C12: TEXT | E12: none | F12: chat | camera | G12: main.py / POST /camera/item | H12: handle_found() wording, ask_lost | I12: camera | J12: Decides whether a reply says "on the shelf" or "reported near ...".
A13: lost_found | B13: status | C13: TEXT | E13: 'open' | F13: open | matched | claim_pending | claimed | G13: default open; handle_found() -> matched (the LOST row); "claim <id>" DM -> claim_pending; camera removal -> claimed | H13: find_matches() (open only), ask_lost, app | I13: open | J13: See the lifecycle on the Overview sheet. Only open found rows are offered as matches.
A14: lost_found | B14: created | C14: TEXT | E14: none | F14: ISO 8601 text: YYYY-MM-DDTHH:MM:SS | G14: db.now() | H14: ordering, app | I14: 2026-10-26T14:40:55 | J14: Stored as text, so keep the exact format.
A15: events | B15: id | C15: INTEGER | D15: PK | E15: auto | F15: whole number >= 1 | G15: SQLite (auto) | H15: ORDER BY id DESC in ask_events | I15: 4
A16: events | B16: title | C16: TEXT | E16: none | F16: short clean title | G16: llm.extract; falls back to first 80 chars of the message | H16: ask_events, alerts, app | I16: Inter-hostel football final | J16: Used as the alert headline, so keep it short.
A17: events | B17: category | C17: TEXT | E17: 'other' in code | F17: sports | music | dance | theatre | culture | tech | academic | other | G17: llm.extract (enum in SCHEMA) | H17: notify_interested(), app cards | I17: sports | J17: Must be one of CATEGORIES in llm.py; students follow these names.
A18: events | B18: date | C18: TEXT | E18: none | F18: free text, e.g. "Friday 5 PM" | G18: llm.extract | H18: alert text, ask_events | I18: Friday 5 PM | J18: Not machine-readable. Needs a real date column before any "events this week" filtering or dedupe-by-date.
A19: events | B19: venue | C19: TEXT | E19: none | F19: free text | G19: llm.extract | H19: alert text, ask_events | I19: Main ground
A20: events | B20: details | C20: TEXT | E20: none | F20: original post text | G20: main.py (text) | H20: app, staff review | I20: Open mic night Sunday 7pm... | J20: Same privacy note as lost_found.details.
A21: events | B21: major | C21: INTEGER | E21: none | F21: 0 | 1 | G21: llm.extract (boolean) -> int | H21: notify_interested() for major-only followers | I21: 1 | J21: 1 = official, fest-level or inter-college; 0 = small club meet-up.
A22: events | B22: source | C22: TEXT | E22: none | F22: name of the WhatsApp group (chat_name); "seed" for /dev/seed rows | G22: main.py (m.chat_name) | H22: staff review | I22: Sports Council | J22: Useful for tracing which group an announcement came from.
A23: events | B23: created | C23: TEXT | E23: none | F23: ISO 8601 text | G23: db.now() | H23: ordering | I23: 2026-10-25T13:15:44
A24: listings | B24: id | C24: INTEGER | D24: PK | E24: auto | F24: whole number >= 1 | G24: SQLite (auto) | H24: ask_listings ordering | I24: 5
A25: listings | B25: kind | C25: TEXT | E25: none | F25: sell | buy | G25: main.py (sell_post -> sell, buy_request -> buy) | H25: sell/buy matching, ask_listings | I25: sell
A26: listings | B26: item | C26: TEXT | E26: none | F26: short noun | G26: llm.extract | H26: token matching between buyers and sellers | I26: cooler | J26: Matching needs a shared word, so "second-hand cycle" matches "cycle".
A27: listings | B27: price | C27: TEXT | E27: none | F27: free text, e.g. "₹2000"; empty for buy requests | G27: llm.extract | H27: seller alert text, ask_listings | I27: ₹2000 | J27: Text, not a number, so price filtering needs parsing first.
A28: listings | B28: details | C28: TEXT | E28: none | F28: original message text | G28: main.py (text) | H28: app | I28: selling my cycle, 2000 rs, barely used | J28: Same privacy note as lost_found.details.
A29: listings | B29: contact | C29: TEXT | E29: none | F29: WhatsApp id | G29: main.py (m.author) | H29: alerts to matching buyers | I29: 919800000009@c.us | J29: Never shown to other students; they must reply to the bot.
A30: listings | B30: status | C30: TEXT | E30: 'open' | F30: open (sold is a suggestion, not used yet) | G30: default open | H30: ask_listings / matching (open only) | I30: open | J30: Nothing closes a listing yet. Add a handler before the demo if stale listings matter.
A31: listings | B31: created | C31: TEXT | E31: none | F31: ISO 8601 text | G31: db.now() | H31: ordering | I31: 2026-10-25T19:10:00
A32: machines | B32: id | C32: TEXT | D32: PK | E32: none | F32: short code, e.g. b8, g3 | G32: POST /camera/machine | H32: ask_laundry | I32: b8 | J32: INSERT OR REPLACE: one row per machine, always the latest state.
A33: machines | B33: location | C33: TEXT | E33: none | F33: free text | G33: POST /camera/machine | H33: ask_laundry replies | I33: 8th floor boys hostel | J33: Students name machines by this text, so the LLM's `machine` field should resemble it.
A34: machines | B34: status | C34: TEXT | E34: none | F34: in use | free | G34: cv_machine.py (motion in a box) | H34: ask_laundry, app | I34: free
A35: machines | B35: updated | C35: TEXT | E35: none | F35: ISO 8601 text | G35: db.now() | H35: ask_laundry (freshness) | I35: 2026-10-27T11:20:05 | J35: A stale timestamp means the camera script stopped reporting.
A36: bookings | B36: id | C36: INTEGER | D36: PK | E36: auto | F36: whole number >= 1 | G36: SQLite (auto) | I36: 3
A37: bookings | B37: room | C37: TEXT | E37: none | F37: lowercase free text, e.g. music room | G37: main.py (llm room, lowercased) | H37: clash check, ask_room | I37: music room | J37: Compared case-insensitively; keep names consistent.
A38: bookings | B38: day | C38: TEXT | E38: none | F38: YYYY-MM-DD | G38: main.py (today only for now) | H38: ask_room, clash check | I38: 2026-10-27 | J38: Column already supports future dates; the handler books today only until the LLM gets a `day` field.
A39: bookings | B39: start | C39: TEXT | E39: none | F39: HH:MM, 24h | G39: llm.extract | H39: overlaps() | I39: 17:00
A40: bookings | B40: end | C40: TEXT | E40: none | F40: HH:MM, 24h (default start + 1h) | G40: llm.extract or main.py default | H40: overlaps() | I40: 18:00 | J40: Back-to-back bookings (18:00 end, 18:00 start) are allowed: the clash test is start < other_end AND other_start < end.
A41: bookings | B41: booked_by | C41: TEXT | E41: none | F41: WhatsApp id | G41: main.py (m.author) | H41: app | I41: 919800000001@c.us
...

Sheet Intent_Map
A1: Intent map: what each message type does to the database
A2: From backend/main.py POST /message. Change a table here and the handler for these intents must change with it (tell Avik).
A4: Intent | B4: Triggered by | C4: Fields used | D4: Writes | E4: Reads | F4: What the student gets back
A5: lost_report | B5: "mera black boat earphones kho gaya" | C5: item, colour, place | D5: lost_found (kind=lost, source=chat); outbox in groups | E5: lost_found (open found rows) | F5: Possible match with a claim prompt, or "Noted ...". In a group the reply goes to the author privately.
A6: found_report | B6: "found a blue jacket in canteen" | C6: item, colour, place | D6: lost_found (kind=found); outbox + UPDATE matching lost row to matched | E6: lost_found (open lost rows) | F6: "Thanks! I've logged it" and, if matched, the owner gets a "Good news!" alert with a claim prompt.
A7: event_post | B7: "Dance club auditions Friday 5pm" | C7: title, category, date, venue, major | D7: events; outbox (one alert per following student) | E7: students | F7: "Event noted". Followers (level all, or major only for major events) are alerted.
A8: sell_post | B8: "selling my cycle 2000 rs" | C8: item, price | D8: listings (kind=sell); outbox (alerts to matching buyers) | E8: listings (open buy rows) | F8: "Listed!" Matching buyers get a private alert.
A9: buy_request | B9: "anyone selling a cooler?" | C9: item | D9: listings (kind=buy) | E9: listings (open sell rows) | F9: "Listed!" plus a count of possible matches.
A10: ask_lost | B10: "has anyone found my earbuds?" | C10: none | D10: nothing | E10: lost_found (found, open, newest 30) | F10: A short written answer built only from those rows.
A11: ask_events | B11: "what events are on this weekend?" | C11: none | D11: nothing | E11: events (newest 20) | F11: Short answer from those rows.
A12: ask_listings | B12: "what's for sale?" | C12: none | D12: nothing | E12: listings (open, newest 20) | F12: Short answer from those rows.
A13: ask_room | B13: "is the music room free at 5?" | C13: room | D13: nothing | E13: bookings (reference day) | F13: Short answer from today's bookings.
A14: book_room | B14: "book the meeting room 3 to 4pm" | C14: room, start, end | D14: bookings (after a clash check) | E14: bookings | F14: "Booked!" or "already booked between ...".
A15: ask_laundry | B15: "is the 8th floor machine free?" | C15: machine | D15: nothing | E15: machines | F15: Short answer from machine rows.
... A20: blocked / skipped / llm_error | B20: safety regex; untagged group chatter with no keyword; Ollama unreachable | C20: none | D20: nothing | E20: nothing | F20: Refusal, silence, or "having trouble thinking".
A22: Non-chat writers (HTTP endpoints)
A23: Endpoint | B23: Called by | C23: Fields | D23: Writes | E23: Reads | F23: Notes
A24: POST /camera/item | B24: cv_shelf.py | C24: item, colour, location | D24: lost_found (kind=found, source=camera); matching lost row -> matched; outbox | E24: lost_found | F24: Returns the matched lost id, if any.
A25: POST /camera/item/{id}/removed | B25: cv_shelf.py | C25: id in URL | D25: lost_found.status -> claimed | E25: nothing | F25: Item left the shelf; assumed collected.
A26: POST /camera/machine | B26: cv_machine.py | C26: id, location, status | D26: machines (INSERT OR REPLACE) | E26: nothing | F26: One row per machine, always the latest state.
A27: POST /preferences | B27: companion app | C27: phone, interests[], level | D27: students (INSERT OR REPLACE) | E27: nothing | F27: 10-digit numbers are prefixed with 91 and suffixed @c.us.
A28: GET /outbox | B28: WhatsApp bot (every 5 s) | C28: none | D28: outbox.sent -> 1 | E28: outbox (sent = 0, oldest 20) | F28: Marks rows sent at fetch time, before delivery.
A29: GET /records/{table} | B29: companion app | C29: table name | D29: nothing | E29: any of the 7 tables (newest 200) | F29: Read-only view used by the dashboards.
A30: POST /dev/seed | B30: developers | C30: none | D30: lost_found, events, listings, machines | E30: nothing | F30: Test data only. Run once after a fresh database.

Sheet SQL_Reference
A1: SQL reference
A2: Copy-paste into DB Browser for SQLite (Execute SQL tab) against backend/vernier.db.
A4: Table | B4: Purpose | C4: SQL
A5: SCHEMA (from db.py init_db)
A6: lost_found | B6: Create table | C6: CREATE TABLE IF NOT EXISTS lost_found( id INTEGER PRIMARY KEY, kind TEXT, item TEXT, colour TEXT, place TEXT, details TEXT, contact TEXT, source TEXT, status TEXT DEFAULT 'open', created TEXT);
A7: events | B7: Create table | C7: CREATE TABLE IF NOT EXISTS events( id INTEGER PRIMARY KEY, title TEXT, category TEXT, date TEXT, venue TEXT, details TEXT, major INTEGER, source TEXT, created TEXT);
A8: listings | B8: Create table | C8: CREATE TABLE IF NOT EXISTS listings( id INTEGER PRIMARY KEY, kind TEXT, item TEXT, price TEXT, details TEXT, contact TEXT, status TEXT DEFAULT 'open', created TEXT);
A9: machines | B9: Create table | C9: CREATE TABLE IF NOT EXISTS machines( id TEXT PRIMARY KEY, location TEXT, status TEXT, updated TEXT);
A10: bookings | B10: Create table | C10: CREATE TABLE IF NOT EXISTS bookings( id INTEGER PRIMARY KEY, room TEXT, day TEXT, start TEXT, end TEXT, booked_by TEXT);
A11: students | B11: Create table | C11: CREATE TABLE IF NOT EXISTS students( contact TEXT PRIMARY KEY, interests TEXT, level TEXT);
A12: outbox | B12: Create table | C12: CREATE TABLE IF NOT EXISTS outbox( id INTEGER PRIMARY KEY, to_chat TEXT, text TEXT, sent INTEGER DEFAULT 0, created TEXT);
A13: QUERIES THE BACKEND RUNS
A14: lost_found | B14: Candidates for matching (find_matches) | C14: SELECT * FROM lost_found WHERE kind = 'found' AND status = 'open';
A15: lost_found | B15: ask_lost answer rows | C15: SELECT id, item, colour, place, source, created FROM lost_found WHERE kind = 'found' AND status = 'open' ORDER BY id DESC LIMIT 30;
A16: events | B16: ask_events answer rows | C16: SELECT title, category, date, venue, major FROM events ORDER BY id DESC LIMIT 20;
A17: listings | B17: ask_listings answer rows | C17: SELECT item, price, kind FROM listings WHERE status = 'open' ORDER BY id DESC LIMIT 20;
A18: bookings | B18: Bookings for a day and room | C18: SELECT room, start, end FROM bookings WHERE day = '2026-10-27' AND lower(room) = 'music room';
A19: outbox | B19: Alerts waiting for the bot (take_outbox) | C19: SELECT id, to_chat, text FROM outbox WHERE sent = 0 ORDER BY id LIMIT 20;
A20: USEFUL CHECKS (proposed, not run by the app)
A21: events | B21: Duplicate events (same title and date) to clean up or dedupe | C21: SELECT title, date, COUNT(*) AS copies FROM events GROUP BY lower(title), lower(date) HAVING COUNT(*) > 1;
A22: lost_found | B22: Lost reports still open after 24 hours | C22: SELECT id, item, colour, place, created FROM lost_found WHERE kind = 'lost' AND status = 'open' AND created < datetime('now', '-1 day');
A23: students | B23: Students whose interests contain an unknown category | C23: SELECT contact, interests FROM students WHERE interests LIKE '% %' OR interests LIKE '%, %';
A24: outbox | B24: Alerts that were fetched but may not have been delivered (review the bot log) | C24: SELECT id, to_chat, substr(text, 1, 60) AS preview, created FROM outbox WHERE sent = 1 ORDER BY id DESC LIMIT 20;
A25: lost_found | B25: Camera items currently on the shelf | C25: SELECT id, item, colour, place FROM lost_found WHERE source = 'camera' AND status IN ('open', 'claim_pending');
A26: ALL TABLES | B26: Reset after a schema change (stop backend first) | C26: -- 1. stop uvicorn 2. delete backend\vernier.db 3. start uvicorn 4. POST /dev/seed at /docs

Sheet lost_found
A1: id | B1: kind | C1: item | D1: colour | E1: place | F1: details | G1: contact | H1: source | I1: status | J1: created
A2: 1 | B2: found | C2: bottle | D2: clear | E2: Rack C, Basket 3 | H2: camera | I2: open | J2: 2026-10-26T09:12:04
A3: 2 | B3: found | C3: hoodie | D3: pink | E3: Rack B, Hanger 4 | H3: camera | I3: claim_pending | J3: 2026-10-26T09:14:31
A4: 3 | B4: found | C4: backpack | D4: purple | E4: Rack B, Bottom | H4: camera | I4: open | J4: 2026-10-26T09:15:10
A5: 4 | B5: found | C5: gloves | D5: black | E5: Rack C, Basket 1 | H5: camera | I5: open | J5: 2026-10-26T09:16:02
A6: 5 | B6: found | C6: lunch bag | D6: blue | E6: Rack A, Shelf 1 | H6: camera | I6: open | J6: 2026-10-26T09:17:45
A7: 6 | B7: lost | C7: earbuds | D7: black | E7: library | F7: lost my black earbuds in library | G7: 919800000001@c.us | H7: chat | I7: matched | J7: 2026-10-26T11:02:19
A8: 7 | B8: found | C8: earbuds | D8: black | E8: library desk | F8: found black earbuds near library desk | G8: 919800000002@c.us | H8: chat | I8: open | J8: 2026-10-26T14:40:55
A9: 8 | B9: lost | C9: bottle | D9: blue | E9: block C canteen | F9: lost my blue water bottle near block C canteen | G9: 919800000003@c.us | H9: chat | I9: open | J9: 2026-10-26T15:05:30
A10: 9 | B10: found | C10: hoodie | D10: grey | E10: room 204 | F10: found a grey hoodie in room 204 after the lecture | G10: 919800000004@c.us | H10: chat | I10: open | J10: 2026-10-26T16:21:12
A11: 10 | B11: found | C11: id card | E11: parking | F11: kisi ka id card mila hai, parking ke paas, DM me | G11: 919800000005@c.us | H11: chat | I11: open | J11: 2026-10-26T17:48:03
A12: 11 | B12: lost | C12: hoodie | D12: pink | E12: auditorium | F12: pink hoodie kho gaya auditorium me | G12: 919800000006@c.us | H12: chat | I12: open | J12: 2026-10-27T08:30:41
A13: 12 | B13: found | C13: umbrella | D13: black | E13: Rack A, Shelf 2 | H13: camera | I13: claimed | J13: 2026-10-24T10:03:27
A14: 13 | B14: lost | C14: keys | E14: hostel gate | F14: keys kho gaye hostel gate ke paas | G14: 919800000007@c.us | H14: chat | I14: open | J14: 2026-10-27T09:12:58
A15: 14 | B15: lost | C15: calculator | D15: grey | E15: exam hall 2 | F15: lost my grey casio calculator in exam hall 2 | G15: 919800000008@c.us | H15: chat | I15: open | J15: 2026-10-27T10:20:36

Sheet events
A1: id | B1: title | C1: category | D1: date | E1: venue | F1: details | G1: major | H1: source | I1: created
A2: 1 | B2: Dance Club auditions | C2: dance | D2: Friday 5 PM | E2: Auditorium | F2: Dance club auditions this Friday 5pm at the auditorium, register now! | G2: 0 | H2: Dance Club Announcements | I2: 2026-10-25T12:00:10
A3: 2 | B3: Inter-hostel football final | C3: sports | D3: Saturday 4 PM | E3: Main ground | F3: Inter-hostel football final on Saturday at the main ground, everyone come support | G3: 1 | H3: Sports Council | I3: 2026-10-25T13:15:44
A4: 3 | B4: Open mic night | C4: music | D4: Sunday 7 PM | E4: Amphitheatre | F4: Open mic night Sunday 7pm at the amphitheatre. Sign up with the music society. | G4: 0 | H4: Music Society | I4: 2026-10-25T18:30:02
A5: 4 | B5: Annual tech fest registrations | C5: tech | D5: This week | E5: Block C | F5: Annual tech fest registrations are open this week at Block C | G5: 1 | H5: Tech Fest Core | I5: 2026-10-26T09:00:15
A6: 5 | B6: Drama Club recruitment | C6: theatre | D6: Monday 4 PM | E6: Seminar Hall 2 | F6: Drama club recruitment Monday 4pm Seminar Hall 2. Freshers welcome. | G6: 0 | H6: Drama Club | I6: 2026-10-26T10:45:51
A7: 6 | B7: Inter-college debate championship | C7: culture | D7: Thursday 10 AM | E7: Main auditorium | F7: Inter-college debate championship Thursday 10am, main auditorium. Register by Wednesday. | G7: 1 | H7: Cultural Committee | I7: 2026-10-26T12:20:33
A8: 7 | B8: Placement prep workshop | C8: academic | D8: Wednesday 11 AM | E8: Block A, Room 105 | F8: Placement prep workshop Wednesday 11am Block A room 105 | G8: 0 | H8: Training & Placement | I8: 2026-10-26T15:10:09
A9: 8 | B9: Rangmanch cultural night | C9: culture | D9: 14 November 6 PM | E9: Open-air theatre | F9: Rangmanch cultural night on 14 November, 6pm at the open-air theatre | G9: 1 | H9: Cultural Committee | I9: 2026-10-26T16:05:27
A10: 9 | B10: Chess club weekly meetup | C10: other | D10: Thursday 6 PM | E10: Common room | F10: Chess club weekly meetup Thursday 6pm common room, all levels | G10: 0 | H10: Chess Club | I10: 2026-10-27T07:55:40
A11: 10 | B11: Hackathon info session | C11: tech | D11: Tuesday 3 PM | E11: Lab 4 | F11: Hackathon info session Tuesday 3pm in Lab 4 | G11: 0 | H11: Coding Club | I11: 2026-10-27T09:40:18

Sheet listings
A1: id | B1: kind | C1: item | D1: price | E1: details | F1: contact | G1: status | H1: created
A2: 1 | B2: sell | C2: cycle | D2: ₹2000 | E2: selling my cycle, 2000 rs, barely used | F2: 919800000009@c.us | G2: open | H2: 2026-10-25T19:10:00
A3: 2 | B3: sell | C3: study table | D3: ₹800 | E3: study table for sale, 800 rs, hostel pickup | F3: 919800000010@c.us | G3: open | H3: 2026-10-25T20:22:41
A4: 3 | B4: sell | C4: engineering drawing kit | D4: ₹300 | E4: selling engineering drawing kit, 300 rs | F4: 919800000011@c.us | G4: open | H4: 2026-10-26T08:14:09
A5: 4 | B5: buy | C5: cooler | E5: anyone selling a cooler? need one for my room | F5: 919800000012@c.us | G5: open | H5: 2026-10-26T13:33:25
A6: 5 | B6: sell | C6: cooler | D6: ₹1500 | E6: cooler for sale 1500, works great | F6: 919800000013@c.us | G6: open | H6: 2026-10-26T18:02:11
A7: 6 | B7: buy | C7: second-hand cycle | E7: looking to buy a second hand cycle, budget around 1500 | F7: 919800000014@c.us | G7: open | H7: 2026-10-27T09:05:37
A8: 7 | B8: sell | C8: lab coat | D8: ₹250 | E8: lab coat size M, 250 rs, used one semester | F8: 919800000015@c.us | G8: open | H8: 2026-10-27T10:48:52

Sheet machines
A1: id | B1: location | C1: status | D1: updated
A2: b8 | B2: 8th floor boys hostel | C2: in use | D2: 2026-10-27T11:20:05
A3: g3 | B3: 3rd floor girls hostel | C3: free | D3: 2026-10-27T11:20:07
A4: b2 | B4: 2nd floor boys hostel | C4: free | D4: 2026-10-27T11:19:58
A5: g5 | B5: 5th floor girls hostel | C5: in use | D5: 2026-10-27T11:20:02

Sheet bookings
A1: id | B1: room | C1: day | D1: start | E1: end | F1: booked_by
A2: 1 | B2: meeting room | C2: 2026-10-27 | D2: 15:00 | E2: 16:00 | F2: 919800000001@c.us
A3: 2 | B3: dance room | C3: 2026-10-27 | D3: 16:00 | E3: 17:30 | F3: 919800000006@c.us
A4: 3 | B4: music room | C4: 2026-10-27 | D4: 17:00 | E4: 18:00 | F4: 919800000001@c.us
A5: 4 | B5: music room | C5: 2026-10-27 | D5: 18:00 | E5: 19:00 | F5: 919800000004@c.us
A6: 5 | B6: meeting room | C6: 2026-10-28 | D6: 15:00 | E6: 16:00 | F6: 919800000005@c.us

Sheet students
A1: contact | B1: interests | C1: level
A2: 919800000001@c.us | B2: dance,music | C2: all
A3: 919800000004@c.us | B3: sports | C3: major
A4: 919800000005@c.us | B4: tech,academic | C4: all
A5: 919800000006@c.us | B5: theatre,culture,music | C5: major
A6: 919800000007@c.us | B6: sports,tech | C6: all
A7: 184467440737095@lid | B7: dance | C7: all

Sheet outbox
A1: id | B1: to_chat | C1: text | D1: sent | E1: created
A2: 1 | B2: 919800000001@c.us | C2: Good news! Something matching your lost black earbuds turned up: black earbuds. Someone found it near library desk. Reply 'claim 7' and tell me one detail only the owner would know. | D2: 1 | E2: 2026-10-26T14:40:56
A3: 2 | B3: 919800000001@c.us | C3: New dance update: Dance Club auditions on Friday 5 PM at Auditorium | D3: 1 | E3: 2026-10-25T12:00:11
A4: 3 | B4: 919800000004@c.us | C4: New sports update: Inter-hostel football final on Saturday 4 PM at Main ground | D4: 1 | E4: 2026-10-25T13:15:45
A5: 4 | B5: 919800000007@c.us | C5: New sports update: Inter-hostel football final on Saturday 4 PM at Main ground | D5: 1 | E5: 2026-10-25T13:15:45
A6: 5 | B6: 919800000005@c.us | C6: New tech update: Annual tech fest registrations on This week at Block C | D6: 0 | E6: 2026-10-26T09:00:16
A7: 6 | B7: 919800000012@c.us | C7: Someone is selling a cooler for ₹1500. Reply here if you want their contact. | D7: 0 | E7: 2026-10-26T18:02:12

Sheet Lists
A1: intent (llm.py INTENTS) | B1: category (llm.py CATEGORIES) | C1: lost_found.kind | D1: lost_found.source | E1: lost_found.status | F1: listings.kind | G1: listings.status | H1: machines.status | I1: students.level | J1: flag (0/1) | K1: rooms (suggested)
A2: lost_report | B2: sports | C2: lost | D2: chat | E2: open | F2: sell | G2: open | H2: in use | I2: all | J2: 0 | K2: music room
A3: found_report | B3: music | C3: found | D3: camera | E3: matched | F3: buy | G3: sold | H3: free | I3: major | J3: 1 | K3: dance room
A4: event_post | B4: dance | E4: claim_pending | K4: meeting room
A5: sell_post | B5: theatre | E5: claimed
A6: buy_request | B6: culture
A7: ask_lost | B7: tech
A8: ask_events | B8: academic
A9: ask_room | B9: other
A10: book_room
A11: ask_laundry
A12: ask_listings
A13: ask_person
A14: chit_chat
A15: other
A18: Edit a list here and every dropdown that uses it updates. Keep these in sync with INTENTS / CATEGORIES in backend/llm.py.
A19: listings.status 'sold' and extra room names are suggestions: main.py does not set them yet.

Sheet Match_Check
A1: Match check: does an open FOUND item exist for each LOST report?
A2: Formulas only: edit lost_found, not this sheet. main.py scores word overlap (Jaccard >= 0.4); this sheet approximates it with an exact item-name match, so it is a quick sanity check, not the real matcher.
A4: id | B4: kind | C4: item | D4: colour | E4: status | F4: Open found items: same item | G4: …same item + colour | H4: Verdict
A5: =IF(lost_found!A2="","",lost_found!A2) -> 1 | B5: =IF(lost_found!B2="","",lost_found!B2) -> found | C5: =IF(lost_found!C2="","",lost_found!C2) -> bottle | D5: =IF(lost_found!D2="","",lost_found!D2) -> clear | E5: =IF(lost_found!I2="","",lost_found!I2) -> open | F5: =IF(OR(B5<>"lost",C5=""),"",COUNTIFS(lost_found!$B$2:$B$1000,"found",lost_found!$C$2:$C$1000,C5,lost_found!$I$2:$I$1000,"open")) | G5: =IF(OR(B5<>"lost",C5=""),"",IF(D5="",F5,COUNTIFS(lost_found!$B$2:$B$1000,"found",lost_found!$C$2:$C$1000,C5,lost_found!$D$2:$D$1000,D5,lost_found!$I$2:$I$1000,"open"))) | H5: =IF(B5<>"lost","",IF(C5="","Needs item",IF(G5>0,"Likely match",IF(F5>0,"Possible (colour differs)","No match yet"))))
A6: =IF(lost_found!A3="","",lost_found!A3) -> 2 | B6: =IF(lost_found!B3="","",lost_found!B3) -> found | C6: =IF(lost_found!C3="","",lost_found!C3) -> hoodie | D6: =IF(lost_found!D3="","",lost_found!D3) -> pink | E6: =IF(lost_found!I3="","",lost_found!I3) -> claim_pending | F6: =IF(OR(B6<>"lost",C6=""),"",COUNTIFS(lost_found!$B$2:$B$1000,"found",lost_found!$C$2:$C$1000,C6,lost_found!$I$2:$I$1000,"open")) | G6: =IF(OR(B6<>"lost",C6=""),"",IF(D6="",F6,COUNTIFS(lost_found!$B$2:$B$1000,"found",lost_found!$C$2:$C$1000,C6,lost_found!$D$2:$D$1000,D6,lost_found!$I$2:$I$1000,"open"))) | H6: =IF(B6<>"lost","",IF(C6="","Needs item",IF(G6>0,"Likely match",IF(F6>0,"Possible (colour differs)","No match yet"))))
A7: =IF(lost_found!A4="","",lost_found!A4) -> 3 | B7: =IF(lost_found!B4="","",lost_found!B4) -> found | C7: =IF(lost_found!C4="","",lost_found!C4) -> backpack | D7: =IF(lost_found!D4="","",lost_found!D4) -> purple | E7: =IF(lost_found!I4="","",lost_found!I4) -> open | F7: =IF(OR(B7<>"lost",C7=""),"",COUNTIFS(lost_found!$B$2:$B$1000,"found",lost_found!$C$2:$C$1000,C7,lost_found!$I$2:$I$1000,"open")) | G7: =IF(OR(B7<>"lost",C7=""),"",IF(D7="",F7,COUNTIFS(lost_found!$B$2:$B$1000,"found",lost_found!$C$2:$C$1000,C7,lost_found!$D$2:$D$1000,D7,lost_found!$I$2:$I$1000,"open"))) | H7: =IF(B7<>"lost","",IF(C7="","Needs item",IF(G7>0,"Likely match",IF(F7>0,"Possible (colour differs)","No match yet"))))
A8: =IF(lost_found!A5="","",lost_found!A5) -> 4 | B8: =IF(lost_found!B5="","",lost_found!B5) -> found | C8: =IF(lost_found!C5="","",lost_found!C5) -> gloves | D8: =IF(lost_found!D5="","",lost_found!D5) -> black | E8: =IF(lost_found!I5="","",lost_found!I5) -> open | F8: =IF(OR(B8<>"lost",C8=""),"",COUNTIFS(lost_found!$B$2:$B$1000,"found",lost_found!$C$2:$C$1000,C8,lost_found!$I$2:$I$1000,"open")) | G8: =IF(OR(B8<>"lost",C8=""),"",IF(D8="",F8,COUNTIFS(lost_found!$B$2:$B$1000,"found",lost_found!$C$2:$C$1000,C8,lost_found!$D$2:$D$1000,D8,lost_found!$I$2:$I$1000,"open"))) | H8: =IF(B8<>"lost","",IF(C8="","Needs item",IF(G8>0,"Likely match",IF(F8>0,"Possible (colour differs)","No match yet"))))
A9: =IF(lost_found!A6="","",lost_found!A6) -> 5 | B9: =IF(lost_found!B6="","",lost_found!B6) -> found | C9: =IF(lost_found!C6="","",lost_found!C6) -> lunch bag | D9: =IF(lost_found!D6="","",lost_found!D6) -> blue | E9: =IF(lost_found!I6="","",lost_found!I6) -> open | F9: =IF(OR(B9<>"lost",C9=""),"",COUNTIFS(lost_found!$B$2:$B$1000,"found",lost_found!$C$2:$C$1000,C9,lost_found!$I$2:$I$1000,"open")) | G9: =IF(OR(B9<>"lost",C9=""),"",IF(D9="",F9,COUNTIFS(lost_found!$B$2:$B$1000,"found",lost_found!$C$2:$C$1000,C9,lost_found!$D$2:$D$1000,D9,lost_found!$I$2:$I$1000,"open"))) | H9: =IF(B9<>"lost","",IF(C9="","Needs item",IF(G9>0,"Likely match",IF(F9>0,"Possible (colour differs)","No match yet"))))
A10: =IF(lost_found!A7="","",lost_found!A7) -> 6 | B10: =IF(lost_found!B7="","",lost_found!B7) -> lost | C10: =IF(lost_found!C7="","",lost_found!C7) -> earbuds | D10: =IF(lost_found!D7="","",lost_found!D7) -> black | E10: =IF(lost_found!I7="","",lost_found!I7) -> matched | F10: =IF(OR(B10<>"lost",C10=""),"",COUNTIFS(lost_found!$B$2:$B$1000,"found",lost_found!$C$2:$C$1000,C10,lost_found!$I$2:$I$1000,"open")) -> 1 | G10: =IF(OR(B10<>"lost",C10=""),"",IF(D10="",F10,COUNTIFS(lost_found!$B$2:$B$1000,"found",lost_found!$C$2:$C$1000,C10,lost_found!$D$2:$D$1000,D10,lost_found!$I$2:$I$1000,"open"))) -> 1 | H10: =IF(B10<>"lost","",IF(C10="","Needs item",IF(G10>0,"Likely match",IF(F10>0,"Possible (colour differs)","No match yet")))) -> Likely match
A11: =IF(lost_found!A8="","",lost_found!A8) -> 7 | B11: =IF(lost_found!B8="","",lost_found!B8) -> found | C11: =IF(lost_found!C8="","",lost_found!C8) -> earbuds | D11: =IF(lost_found!D8="","",lost_found!D8) -> black | E11: =IF(lost_found!I8="","",lost_found!I8) -> open | F11: =IF(OR(B11<>"lost",C11=""),"",COUNTIFS(lost_found!$B$2:$B$1000,"found",lost_found!$C$2:$C$1000,C11,lost_found!$I$2:$I$1000,"open")) | G11: =IF(OR(B11<>"lost",C11=""),"",IF(D11="",F11,COUNTIFS(lost_found!$B$2:$B$1000,"found",lost_found!$C$2:$C$1000,C11,lost_found!$D$2:$D$1000,D11,lost_found!$I$2:$I$1000,"open"))) | H11: =IF(B11<>"lost","",IF(C11="","Needs item",IF(G11>0,"Likely match",IF(F11>0,"Possible (colour differs)","No match yet"))))
A12: =IF(lost_found!A9="","",lost_found!A9) -> 8 | B12: =IF(lost_found!B9="","",lost_found!B9) -> lost | C12: =IF(lost_found!C9="","",lost_found!C9) -> bottle | D12: =IF(lost_found!D9="","",lost_found!D9) -> blue | E12: =IF(lost_found!I9="","",lost_found!I9) -> open | F12: =IF(OR(B12<>"lost",C12=""),"",COUNTIFS(lost_found!$B$2:$B$1000,"found",lost_found!$C$2:$C$1000,C12,lost_found!$I$2:$I$1000,"open")) -> 1 | G12: =IF(OR(B12<>"lost",C12=""),"",IF(D12="",F12,COUNTIFS(lost_found!$B$2:$B$1000,"found",lost_found!$C$2:$C$1000,C12,lost_found!$D$2:$D$1000,D12,lost_found!$I$2:$I$1000,"open"))) -> 0 | H12: =IF(B12<>"lost","",IF(C12="","Needs item",IF(G12>0,"Likely match",IF(F12>0,"Possible (colour differs)","No match yet")))) -> Possible (colour differs)
A13: =IF(lost_found!A10="","",lost_found!A10) -> 9 | B13: =IF(lost_found!B10="","",lost_found!B10) -> found | C13: =IF(lost_found!C10="","",lost_found!C10) -> hoodie | D13: =IF(lost_found!D10="","",lost_found!D10) -> grey | E13: =IF(lost_found!I10="","",lost_found!I10) -> open | F13: =IF(OR(B13<>"lost",C13=""),"",COUNTIFS(lost_found!$B$2:$B$1000,"found",lost_found!$C$2:$C$1000,C13,lost_found!$I$2:$I$1000,"open")) | G13: =IF(OR(B13<>"lost",C13=""),"",IF(D13="",F13,COUNTIFS(lost_found!$B$2:$B$1000,"found",lost_found!$C$2:$C$1000,C13,lost_found!$D$2:$D$1000,D13,lost_found!$I$2:$I$1000,"open"))) | H13: =IF(B13<>"lost","",IF(C13="","Needs item",IF(G13>0,"Likely match",IF(F13>0,"Possible (colour differs)","No match yet"))))
A14: =IF(lost_found!A11="","",lost_found!A11) -> 10 | B14: =IF(lost_found!B11="","",lost_found!B11) -> found | C14: =IF(lost_found!C11="","",lost_found!C11) -> id card | D14: =IF(lost_found!D11="","",lost_found!D11) | E14: =IF(lost_found!I11="","",lost_found!I11) -> open | F14: =IF(OR(B14<>"lost",C14=""),"",COUNTIFS(lost_found!$B$2:$B$1000,"found",lost_found!$C$2:$C$1000,C14,lost_found!$I$2:$I$1000,"open")) | G14: =IF(OR(B14<>"lost",C14=""),"",IF(D14="",F14,COUNTIFS(lost_found!$B$2:$B$1000,"found",lost_found!$C$2:$C$1000,C14,lost_found!$D$2:$D$1000,D14,lost_found!$I$2:$I$1000,"open"))) | H14: =IF(B14<>"lost","",IF(C14="","Needs item",IF(G14>0,"Likely match",IF(F14>0,"Possible (colour differs)","No match yet"))))
A15: =IF(lost_found!A12="","",lost_found!A12) -> 11 | B15: =IF(lost_found!B12="","",lost_found!B12) -> lost | C15: =IF(lost_found!C12="","",lost_found!C12) -> hoodie | D15: =IF(lost_found!D12="","",lost_found!D12) -> pink | E15: =IF(lost_found!I12="","",lost_found!I12) -> open | F15: =IF(OR(B15<>"lost",C15=""),"",COUNTIFS(lost_found!$B$2:$B$1000,"found",lost_found!$C$2:$C$1000,C15,lost_found!$I$2:$I$1000,"open")) -> 1 | G15: =IF(OR(B15<>"lost",C15=""),"",IF(D15="",F15,COUNTIFS(lost_found!$B$2:$B$1000,"found",lost_found!$C$2:$C$1000,C15,lost_found!$D$2:$D$1000,D15,lost_found!$I$2:$I$1000,"open"))) -> 0 | H15: =IF(B15<>"lost","",IF(C15="","Needs item",IF(G15>0,"Likely match",IF(F15>0,"Possible (colour differs)","No match yet")))) -> Possible (colour differs)
A16: =IF(lost_found!A13="","",lost_found!A13) -> 12 | B16: =IF(lost_found!B13="","",lost_found!B13) -> found | C16: =IF(lost_found!C13="","",lost_found!C13) -> umbrella | D16: =IF(lost_found!D13="","",lost_found!D13) -> black | E16: =IF(lost_found!I13="","",lost_found!I13) -> claimed | F16: =IF(OR(B16<>"lost",C16=""),"",COUNTIFS(lost_found!$B$2:$B$1000,"found",lost_found!$C$2:$C$1000,C16,lost_found!$I$2:$I$1000,"open")) | G16: =IF(OR(B16<>"lost",C16=""),"",IF(D16="",F16,COUNTIFS(lost_found!$B$2:$B$1000,"found",lost_found!$C$2:$C$1000,C16,lost_found!$D$2:$D$1000,D16,lost_found!$I$2:$I$1000,"open"))) | H16: =IF(B16<>"lost","",IF(C16="","Needs item",IF(G16>0,"Likely match",IF(F16>0,"Possible (colour differs)","No match yet"))))
... A64: =IF(lost_found!A61="","",lost_found!A61) | B64: =IF(lost_found!B61="","",lost_found!B61) | C64: =IF(lost_found!C61="","",lost_found!C61) | D64: =IF(lost_found!D61="","",lost_found!D61) | E64: =IF(lost_found!I61="","",lost_found!I61) | F64: =IF(OR(B64<>"lost",C64=""),"",COUNTIFS(lost_found!$B$2:$B$1000,"found",lost_found!$C$2:$C$1000,C64,lost_found!$I$2:$I$1000,"open")) | G64: =IF(OR(B64<>"lost",C64=""),"",IF(D64="",F64,COUNTIFS(lost_found!$B$2:$B$1000,"found",lost_found!$C$2:$C$1000,C64,lost_found!$D$2:$D$1000,D64,lost_found!$I$2:$I$1000,"open"))) | H64: =IF(B64<>"lost","",IF(C64="","Needs item",IF(G64>0,"Likely match",IF(F64>0,"Possible (colour differs)","No match yet"))))

Sheet Change_Log
A1: Change log and change procedure
A2: Procedure for any column change: (1) tell Avik (main.py) and Hitarth (app) first, (2) edit init_db() in db.py, (3) stop the backend, delete vernier.db, start it again, (4) POST /dev/seed, (5) update the Data_Dictionary and log it here.
A4: Date | B4: Change | C4: Table / column | D4: Proposed by | E4: Needs sign-off from | F4: Status | G4: Notes
A5: 2026-10-27 | B5: Workbook created from db.py init_db() and main.py | C5: all 7 tables | D5: Arushi | E5: none | F5: Done | G5: Sample rows are fictional; contacts use made-up 9198000000xx ids.
B6: Photo reference for camera-detected items | C6: lost_found.photo (TEXT, new) | D6: Shivam / Arushi | E6: Avik, Hitarth | F6: Proposed | G6: Needed only if the app shows item photos. Raises a privacy review: frame objects, never faces.
B7: Real date for events | C7: events.date_iso (TEXT YYYY-MM-DD, new) | D7: Arushi | E7: Avik, Hitarth | F7: Proposed | G7: Enables "this weekend" queries and dedupe by date. Keep events.date as the human text.
B8: Dedupe helper for forwarded event posts | C8: events (title + date) | D8: Arushi | E8: Avik (call before INSERT) | F8: Proposed | G8: No schema change; a helper function in db.py.
B9: Close sold listings | C9: listings.status = sold | D9: Arushi | E9: Avik | F9: Proposed | G9: Nothing sets sold yet.
B10: Store extracted fields only, not raw message text | C10: lost_found / events / listings .details | D10: Arushi | E10: Avik | F10: Proposed | G10: Matches the pitch line "stores extracted facts, not raw chats".
B11: Mark outbox rows sent after delivery, not at fetch | C11: outbox.sent | D11: Arushi | E11: Avik (bot ack endpoint) | F11: Proposed | G11: Today a crash between fetch and send loses the alert.
